# Generated by Django 2.2.16 on 2021-12-20 11:20

import datetime
import django.contrib.auth.validators
from django.db import migrations, models
from django.utils.timezone import utc


class Migration(migrations.Migration):

    dependencies = [
        ('reviews', '0003_auto_20211220_0738'),
    ]

    operations = [
        migrations.AlterField(
            model_name='comment',
            name='pub_date',
            field=models.DateTimeField(default=datetime.datetime(2021, 12, 20, 11, 20, 51, 960494, tzinfo=utc)),
        ),
        migrations.AlterField(
            model_name='review',
            name='pub_date',
            field=models.DateTimeField(default=datetime.datetime(2021, 12, 20, 11, 20, 51, 960494, tzinfo=utc)),
        ),
        migrations.AlterField(
            model_name='user',
            name='confirmation_code',
            field=models.CharField(default='edaf7a2b676b0b4317fb3214dbd5d1', max_length=30, verbose_name='Код подтверждения'),
        ),
        migrations.AlterField(
            model_name='user',
            name='role',
            field=models.CharField(choices=[('admin', 'Администратор'), ('user', 'Аутентифицированный пользователь'), ('moderator', 'Модератор')], default='user', max_length=50, verbose_name='Роль'),
        ),
        migrations.AlterField(
            model_name='user',
            name='username',
            field=models.CharField(error_messages={'unique': 'A user with that username already exists.'}, help_text='Required. 150 characters or fewer. Letters, digits and @/./+/-/_ only.', max_length=150, unique=True, validators=[django.contrib.auth.validators.UnicodeUsernameValidator()], verbose_name='username'),
        ),
    ]
